<?xml version="1.0"?>
<robot name="hinge_r" xmlns:xacro="http://www.ros.org/wiki/xacro">
 
  <!-- Wheels -->
  <property name="hinge_radius" value="0.2" /> 
  <property name="hinge_height" value="0.1" />
  <property name="hinge_mass" value="0.1" /> <!-- in kg-->
  <property name="lr" value="right" /> <!-- in kg-->
 
  <property name="base_x_origin_to_hinge_origin" value="0.25" />
  <property name="base_y_origin_to_hinge_origin" value="0.3" />
  <property name="base_z_origin_to_hinge_origin" value="0.0" />
 
  <macro name="cylinder_inertia" params="m r h">
    <inertia  ixx="${m*(3*r*r+h*h)/12}" ixy = "0" ixz = "0"
              iyy="${m*(3*r*r+h*h)/12}" iyz = "0"
              izz="${m*r*r/2}" /> 
  </macro>
 
  <xacro:macro name="hinge_r" params="parent translateX translateY flipY"> <!--lr: left, right -->
    <link name="front_right_hinge">
      <visual>
        <origin xyz="0 0 0" rpy="0 0 ${flipY*M_PI/2}" /> 
        <geometry>
        <box size="0.01 0.01 0.01"/>
          <!--<cylinder length="${hinge_height}" radius="${hinge_radius}" />-->
        </geometry>
        <material name="DarkGray" />
      </visual>
      <collision>
        <origin xyz="0 0 0" rpy="0 0 ${flipY*M_PI/2}" />
        <geometry>
        <box size="0.01 0.01 0.01"/>
          <!--<cylinder length="${hinge_height}" radius="${hinge_radius}" />-->
        </geometry>
      </collision>
      <inertial>
        <mass value="${hinge_mass}" />
        <origin xyz="0 0 0" />
        <cylinder_inertia  m="${hinge_mass}" r="${hinge_radius}" h="${hinge_height}" />
      </inertial>
    </link>
 
    <gazebo reference="front_right_hinge">
      <mu1 value="1.0"/>
      <mu2 value="1.0"/>
      <kp  value="10000000.0" />
      <kd  value="1.0" />
      <fdir1 value="1 0 0"/>
      <material>Gazebo/Grey</material>
      <turnGravityOff>false</turnGravityOff>
    </gazebo>
 
    <joint name="front_right_hinge_joint" type="revolute">
      <parent link="${parent}"/>
      <child link="front_right_hinge"/>
      <origin xyz="${translateX * base_x_origin_to_hinge_origin} ${translateY * base_y_origin_to_hinge_origin} ${base_z_origin_to_hinge_origin}" rpy="0 0 0" /> 
      <axis xyz="0 0 -1" rpy="0 1.5708 0" />
      <limit lower="-0.5" upper="0.5" effort="10" velocity="100"/>
      <joint_properties damping="0.0" friction="0.0"/>
    </joint>
 
    <!-- Transmission is important to link the joints and the controller -->
    <transmission name="front_right_hinge_joint_trans">
      <type>transmission_interface/SimpleTransmission</type>
      <joint name="front_right_hinge_joint">
        <hardwareInterface>EffortJointInterface</hardwareInterface>
      </joint>
      <actuator name="front_right_hinge_joint_motor">
        <hardwareInterface>EffortJointInterface</hardwareInterface>
        <mechanicalReduction>1</mechanicalReduction>
      </actuator>
    </transmission>
 
  </xacro:macro>
</robot>